================================================================================
load pg_denormalized
================================================================================
COPY 2979992
COPY 3038917
COPY 3044365
COPY 3189325
COPY 3143286
COPY 3129896
COPY 3148130
COPY 3157691
COPY 3306556
COPY 3376266
1620.07user 360.85system 1:15:07elapsed 43%CPU (0avgtext+0avgdata 17636maxresident)k
14485248inputs+105200outputs (0major+71051minor)pagefaults 0swaps
================================================================================
load pg_normalized_batch
================================================================================
2024-04-23 23:22:15.525484 /data/tweets/geoTwitter21-01-01.zip
2024-04-23 23:22:30.086281 insert_tweets i= 0
Traceback (most recent call last):
  File "/home/sfullerton24/twitter_postgres_indexes/load_tweets_batch.py", line 458, in <module>
    insert_tweets(connection,tweets,args.batch_size)
  File "/home/sfullerton24/twitter_postgres_indexes/load_tweets_batch.py", line 175, in insert_tweets
    _insert_tweets(connection, tweet_batch)
  File "/home/sfullerton24/twitter_postgres_indexes/load_tweets_batch.py", line 394, in _insert_tweets
    with connection.begin() as trans:
         ^^^^^^^^^^^^^^^^^^
  File "/home/sfullerton24/python/lib/python3.11/site-packages/sqlalchemy/engine/base.py", line 867, in begin
    raise exc.InvalidRequestError(
sqlalchemy.exc.InvalidRequestError: This connection has already initialized a SQLAlchemy Transaction() object via begin() or autobegin; can't call begin() here unless rollback() or commit() is called first.
2024-04-23 23:22:15.546602 /data/tweets/geoTwitter21-01-03.zip
2024-04-23 23:22:31.770609 insert_tweets i= 0
Traceback (most recent call last):
  File "/home/sfullerton24/twitter_postgres_indexes/load_tweets_batch.py", line 458, in <module>
    insert_tweets(connection,tweets,args.batch_size)
  File "/home/sfullerton24/twitter_postgres_indexes/load_tweets_batch.py", line 175, in insert_tweets
    _insert_tweets(connection, tweet_batch)
  File "/home/sfullerton24/twitter_postgres_indexes/load_tweets_batch.py", line 394, in _insert_tweets
    with connection.begin() as trans:
         ^^^^^^^^^^^^^^^^^^
  File "/home/sfullerton24/python/lib/python3.11/site-packages/sqlalchemy/engine/base.py", line 867, in begin
    raise exc.InvalidRequestError(
sqlalchemy.exc.InvalidRequestError: This connection has already initialized a SQLAlchemy Transaction() object via begin() or autobegin; can't call begin() here unless rollback() or commit() is called first.
2024-04-23 23:22:15.521803 /data/tweets/geoTwitter21-01-02.zip
2024-04-23 23:22:32.629157 insert_tweets i= 0
Traceback (most recent call last):
  File "/home/sfullerton24/twitter_postgres_indexes/load_tweets_batch.py", line 458, in <module>
    insert_tweets(connection,tweets,args.batch_size)
  File "/home/sfullerton24/twitter_postgres_indexes/load_tweets_batch.py", line 175, in insert_tweets
    _insert_tweets(connection, tweet_batch)
  File "/home/sfullerton24/twitter_postgres_indexes/load_tweets_batch.py", line 394, in _insert_tweets
    with connection.begin() as trans:
         ^^^^^^^^^^^^^^^^^^
  File "/home/sfullerton24/python/lib/python3.11/site-packages/sqlalchemy/engine/base.py", line 867, in begin
    raise exc.InvalidRequestError(
sqlalchemy.exc.InvalidRequestError: This connection has already initialized a SQLAlchemy Transaction() object via begin() or autobegin; can't call begin() here unless rollback() or commit() is called first.
2024-04-23 23:22:15.567356 /data/tweets/geoTwitter21-01-09.zip
2024-04-23 23:22:32.892835 insert_tweets i= 0
Traceback (most recent call last):
  File "/home/sfullerton24/twitter_postgres_indexes/load_tweets_batch.py", line 458, in <module>
    insert_tweets(connection,tweets,args.batch_size)
  File "/home/sfullerton24/twitter_postgres_indexes/load_tweets_batch.py", line 175, in insert_tweets
    _insert_tweets(connection, tweet_batch)
  File "/home/sfullerton24/twitter_postgres_indexes/load_tweets_batch.py", line 394, in _insert_tweets
    with connection.begin() as trans:
         ^^^^^^^^^^^^^^^^^^
  File "/home/sfullerton24/python/lib/python3.11/site-packages/sqlalchemy/engine/base.py", line 867, in begin
    raise exc.InvalidRequestError(
sqlalchemy.exc.InvalidRequestError: This connection has already initialized a SQLAlchemy Transaction() object via begin() or autobegin; can't call begin() here unless rollback() or commit() is called first.
2024-04-23 23:22:15.616707 /data/tweets/geoTwitter21-01-07.zip
2024-04-23 23:22:33.688026 insert_tweets i= 0
Traceback (most recent call last):
  File "/home/sfullerton24/twitter_postgres_indexes/load_tweets_batch.py", line 458, in <module>
    insert_tweets(connection,tweets,args.batch_size)
  File "/home/sfullerton24/twitter_postgres_indexes/load_tweets_batch.py", line 175, in insert_tweets
    _insert_tweets(connection, tweet_batch)
  File "/home/sfullerton24/twitter_postgres_indexes/load_tweets_batch.py", line 394, in _insert_tweets
    with connection.begin() as trans:
         ^^^^^^^^^^^^^^^^^^
  File "/home/sfullerton24/python/lib/python3.11/site-packages/sqlalchemy/engine/base.py", line 867, in begin
    raise exc.InvalidRequestError(
sqlalchemy.exc.InvalidRequestError: This connection has already initialized a SQLAlchemy Transaction() object via begin() or autobegin; can't call begin() here unless rollback() or commit() is called first.
2024-04-23 23:22:15.548180 /data/tweets/geoTwitter21-01-04.zip
2024-04-23 23:22:34.209731 insert_tweets i= 0
Traceback (most recent call last):
  File "/home/sfullerton24/twitter_postgres_indexes/load_tweets_batch.py", line 458, in <module>
    insert_tweets(connection,tweets,args.batch_size)
  File "/home/sfullerton24/twitter_postgres_indexes/load_tweets_batch.py", line 175, in insert_tweets
    _insert_tweets(connection, tweet_batch)
  File "/home/sfullerton24/twitter_postgres_indexes/load_tweets_batch.py", line 394, in _insert_tweets
    with connection.begin() as trans:
         ^^^^^^^^^^^^^^^^^^
  File "/home/sfullerton24/python/lib/python3.11/site-packages/sqlalchemy/engine/base.py", line 867, in begin
    raise exc.InvalidRequestError(
sqlalchemy.exc.InvalidRequestError: This connection has already initialized a SQLAlchemy Transaction() object via begin() or autobegin; can't call begin() here unless rollback() or commit() is called first.
2024-04-23 23:22:15.556189 /data/tweets/geoTwitter21-01-10.zip
2024-04-23 23:22:34.348442 insert_tweets i= 0
Traceback (most recent call last):
  File "/home/sfullerton24/twitter_postgres_indexes/load_tweets_batch.py", line 458, in <module>
    insert_tweets(connection,tweets,args.batch_size)
  File "/home/sfullerton24/twitter_postgres_indexes/load_tweets_batch.py", line 175, in insert_tweets
    _insert_tweets(connection, tweet_batch)
  File "/home/sfullerton24/twitter_postgres_indexes/load_tweets_batch.py", line 394, in _insert_tweets
    with connection.begin() as trans:
         ^^^^^^^^^^^^^^^^^^
  File "/home/sfullerton24/python/lib/python3.11/site-packages/sqlalchemy/engine/base.py", line 867, in begin
    raise exc.InvalidRequestError(
sqlalchemy.exc.InvalidRequestError: This connection has already initialized a SQLAlchemy Transaction() object via begin() or autobegin; can't call begin() here unless rollback() or commit() is called first.
2024-04-23 23:22:15.519781 /data/tweets/geoTwitter21-01-05.zip
2024-04-23 23:22:34.799642 insert_tweets i= 0
Traceback (most recent call last):
  File "/home/sfullerton24/twitter_postgres_indexes/load_tweets_batch.py", line 458, in <module>
    insert_tweets(connection,tweets,args.batch_size)
  File "/home/sfullerton24/twitter_postgres_indexes/load_tweets_batch.py", line 175, in insert_tweets
    _insert_tweets(connection, tweet_batch)
  File "/home/sfullerton24/twitter_postgres_indexes/load_tweets_batch.py", line 394, in _insert_tweets
    with connection.begin() as trans:
         ^^^^^^^^^^^^^^^^^^
  File "/home/sfullerton24/python/lib/python3.11/site-packages/sqlalchemy/engine/base.py", line 867, in begin
    raise exc.InvalidRequestError(
sqlalchemy.exc.InvalidRequestError: This connection has already initialized a SQLAlchemy Transaction() object via begin() or autobegin; can't call begin() here unless rollback() or commit() is called first.
2024-04-23 23:22:15.556590 /data/tweets/geoTwitter21-01-08.zip
2024-04-23 23:22:36.137608 insert_tweets i= 0
Traceback (most recent call last):
  File "/home/sfullerton24/twitter_postgres_indexes/load_tweets_batch.py", line 458, in <module>
    insert_tweets(connection,tweets,args.batch_size)
  File "/home/sfullerton24/twitter_postgres_indexes/load_tweets_batch.py", line 175, in insert_tweets
    _insert_tweets(connection, tweet_batch)
  File "/home/sfullerton24/twitter_postgres_indexes/load_tweets_batch.py", line 394, in _insert_tweets
    with connection.begin() as trans:
         ^^^^^^^^^^^^^^^^^^
  File "/home/sfullerton24/python/lib/python3.11/site-packages/sqlalchemy/engine/base.py", line 867, in begin
    raise exc.InvalidRequestError(
sqlalchemy.exc.InvalidRequestError: This connection has already initialized a SQLAlchemy Transaction() object via begin() or autobegin; can't call begin() here unless rollback() or commit() is called first.
2024-04-23 23:22:15.483898 /data/tweets/geoTwitter21-01-06.zip
2024-04-23 23:22:37.282330 insert_tweets i= 0
Traceback (most recent call last):
  File "/home/sfullerton24/twitter_postgres_indexes/load_tweets_batch.py", line 458, in <module>
    insert_tweets(connection,tweets,args.batch_size)
  File "/home/sfullerton24/twitter_postgres_indexes/load_tweets_batch.py", line 175, in insert_tweets
    _insert_tweets(connection, tweet_batch)
  File "/home/sfullerton24/twitter_postgres_indexes/load_tweets_batch.py", line 394, in _insert_tweets
    with connection.begin() as trans:
         ^^^^^^^^^^^^^^^^^^
  File "/home/sfullerton24/python/lib/python3.11/site-packages/sqlalchemy/engine/base.py", line 867, in begin
    raise exc.InvalidRequestError(
sqlalchemy.exc.InvalidRequestError: This connection has already initialized a SQLAlchemy Transaction() object via begin() or autobegin; can't call begin() here unless rollback() or commit() is called first.
Command exited with non-zero status 10
221.66user 21.94system 0:29.29elapsed 831%CPU (0avgtext+0avgdata 2850876maxresident)k
9984inputs+4136outputs (35major+9852732minor)pagefaults 0swaps
